<?xml version="1.0"?>
<robot name="pan_tilt">

  <link name="base_link">

    <visual>
      <geometry>
				<cylinder length="0.01" radius="0.2"/>
      </geometry>
      <origin rpy="0 0 0" xyz="0 0 0"/>
      <material name="yellow">
        <color rgba="1 1 0 1"/>
      </material>
    </visual>

    <collision>
      <geometry>
				<cylinder length="0.03" radius="0.2"/>
      </geometry>
      <origin rpy="0 0 0" xyz="0 0 0"/>
    </collision>
    <inertial>
			<mass value="10"/>
      <inertia ixx="1" ixy="0.0" ixz="0.0" iyy="1" iyz="0.0" izz="1"/>
    </inertial>
  </link>

	<gazebo reference="base_link">
    <selfCollide>false</selfCollide>
    <material>Gazebo/Yellow</material>
	</gazebo>

  <joint name="pan_joint" type="revolute">
    <parent link="base_link"/>
    <child link="pan_link"/>
    <origin xyz="0 0 0.1"/>
    <axis xyz="0 0 1" />
    <limit effort="300" velocity="0.1" lower="-3.14" upper="3.14"/>
    <dynamics damping="5" friction="1"/>
  </joint>

  <link name="pan_link">
    <visual>
      <geometry>
				<cylinder length="0.4" radius="0.04"/>
      </geometry>
      <origin rpy="0 0 0" xyz="0 0 0.1"/>
      <material name="blue">
        <color rgba="0 0 1 1"/>
      </material>
    </visual>
    <collision>
      <geometry>
				<cylinder length="0.4" radius="0.06"/>
      </geometry>
      <origin rpy="0 0 0" xyz="0 0 0.1"/>
    </collision>
    <inertial>
			<mass value="1"/>
      <inertia ixx="0.1" ixy="0.0" ixz="0.0" iyy="0.1" iyz="0.0" izz="0.1"/>
    </inertial>
  </link>

	<gazebo reference="pan_link">
    <selfCollide>false</selfCollide>
    <material>Gazebo/Blue</material>
	</gazebo>

  <joint name="tilt_joint" type="revolute">
    <parent link="pan_link"/>
    <child link="tilt_link"/>
    <origin xyz="0 0 0.2"/>
    <axis xyz="0 1 0" />
    <limit effort="300" velocity="0.1" lower="-4.64" upper="-1.5"/>
    <dynamics damping="5" friction="1"/>
  </joint>

  <link name="tilt_link">
    <visual>
      <geometry>
				<cylinder length="0.4" radius="0.04"/>
      </geometry>
      <origin rpy="0 1.5 0" xyz="0 0 0"/>
      <material name="red">
        <color rgba="1 0 0 1"/>
      </material>
    </visual>
    <collision>
      <geometry>
				<cylinder length="0.4" radius="0.06"/>
      </geometry>
      <origin rpy="0 1.5 0" xyz="0 0 0"/>
    </collision>
    <inertial>
			<mass value="1"/>
      <inertia ixx="0.1" ixy="0.0" ixz="0.0" iyy="0.1" iyz="0.0" izz="0.1"/>
    </inertial>

  </link>

	<gazebo reference="tilt_link">
    <selfCollide>false</selfCollide>
    <material>Gazebo/Red</material>
	</gazebo>

	<gazebo>
		<plugin name="joint_state_publisher" filename="libgazebo_ros_joint_state_publisher.so">
      <ros>
        <remapping>~/out:=joint_states</remapping>
      </ros>
      <update_rate>30</update_rate>
      <joint_name>pan_joint</joint_name>
      <joint_name>tilt_joint</joint_name>
    </plugin>
		<plugin name="pan_joint_control" filename="libjoint_control.so">
			<update_rate>100</update_rate>
			<joint_name>pan_joint</joint_name>
			<topic_name>pan_topic</topic_name>
			<pid_gain>2000 2 10.003</pid_gain>
			<i_range>0 0</i_range>
    </plugin>
		<plugin name="tilt_joint_control" filename="libjoint_control.so">
			<update_rate>100</update_rate>
			<joint_name>tilt_joint</joint_name>
			<topic_name>tilt_topic</topic_name>
			<pid_gain>2000 2 10.003</pid_gain>
			<i_range>0 0</i_range>
    </plugin>
	</gazebo>

</robot>
